Workbook

Sheet 종합
B1: Q2. AES 암호화 과정을 아래의 평문과 암호를 이용하여 수행하시오.
B2: 모든 과정을 나타내는 것이 아닌 중간과정인 1, 2라운드의 보조키 생성, 암호문 생성한 결과를 표에 채우세요.
B3: 중간 연산은 엑셀의 다른 시트에 자세히 표시하고 주석을 달아주세요.
B5: 1-1) AES의 키
B6: AES 암호 알고리즘은 유한체 8비트의 값으로 데이터가 구성되며, 키의 값은 경우에 따라 128, 196, 256비트로 구성됨
B7: 현재는 128비트(16바이트)의 키를 기준으로 풀이함
B9: Key | C9: 2b7e151628aed2a6abf7158809cf4f3c | I9: 바이트 단위 인덱스 | K9: 0 | L9: 1 | M9: 2 | N9: 3 | O9: 4 | P9: 5 | Q9: 6 | R9: 7 | S9: 8 | T9: 9 | U9: 10 | V9: 11 | W9: 12 | X9: 13 | Y9: 14 | Z9: 15
I10: 위치에 해당하는 값(HEX) | K10: =MID($C9,2*K9+1,2) -> 2b | L10: =MID($C9,2*L9+1,2) -> 7e | M10: =MID($C9,2*M9+1,2) -> 15 | N10: =MID($C9,2*N9+1,2) -> 16 | O10: =MID($C9,2*O9+1,2) -> 28 | P10: =MID($C9,2*P9+1,2) -> ae | Q10: =MID($C9,2*Q9+1,2) -> d2 | R10: =MID($C9,2*R9+1,2) -> a6 | ... Z10: =MID($C9,2*Z9+1,2) -> 3c
D11: 0 | E11: 1 | F11: 2 | G11: 3
C12: 0 | D12: =INDEX($K$10:$Z$10,4*D$11+$C12+1) -> 2b | E12: =INDEX($K$10:$Z$10,4*E$11+$C12+1) -> 28 | F12: =INDEX($K$10:$Z$10,4*F$11+$C12+1) -> ab | G12: =INDEX($K$10:$Z$10,4*G$11+$C12+1) -> 09
C13: 1 | D13: =INDEX($K$10:$Z$10,4*D$11+$C13+1) -> 7e | E13: =INDEX($K$10:$Z$10,4*E$11+$C13+1) -> ae | F13: =INDEX($K$10:$Z$10,4*F$11+$C13+1) -> f7 | G13: =INDEX($K$10:$Z$10,4*G$11+$C13+1) -> cf
C14: 2 | D14: =INDEX($K$10:$Z$10,4*D$11+$C14+1) -> 15 | E14: =INDEX($K$10:$Z$10,4*E$11+$C14+1) -> d2 | F14: =INDEX($K$10:$Z$10,4*F$11+$C14+1) -> 15 | G14: =INDEX($K$10:$Z$10,4*G$11+$C14+1) -> 4f
C15: 3 | D15: =INDEX($K$10:$Z$10,4*D$11+$C15+1) -> 16 | E15: =INDEX($K$10:$Z$10,4*E$11+$C15+1) -> a6 | F15: =INDEX($K$10:$Z$10,4*F$11+$C15+1) -> 88 | G15: =INDEX($K$10:$Z$10,4*G$11+$C15+1) -> 3c
B17: 1-2) AES의 평문
B18: AES 암호 알고리즘은 유한체 8비트의 값으로 데이터가 구성되며, 평문은 키크기와 상관없이 128비트(16바이트)로 구성됨
B20: State | C20: 3243f6a8885a308d313198a2e0370734 | I20: 바이트 단위 인덱스 | K20: 0 | L20: 1 | M20: 2 | N20: 3 | O20: 4 | P20: 5 | Q20: 6 | R20: 7 | S20: 8 | T20: 9 | U20: 10 | V20: 11 | W20: 12 | X20: 13 | Y20: 14 | Z20: 15
I21: 위치에 해당하는 값(HEX) | K21: =MID($C20,2*K20+1,2) -> 32 | L21: =MID($C20,2*L20+1,2) -> 43 | M21: =MID($C20,2*M20+1,2) -> f6 | N21: =MID($C20,2*N20+1,2) -> a8 | O21: =MID($C20,2*O20+1,2) -> 88 | P21: =MID($C20,2*P20+1,2) -> 5a | Q21: =MID($C20,2*Q20+1,2) -> 30 | R21: =MID($C20,2*R20+1,2) -> 8d | ... Z21: =MID($C20,2*Z20+1,2) -> 34
D22: 0 | E22: 1 | F22: 2 | G22: 3
C23: 0 | D23: =INDEX($K$21:$Z$21,4*D$22+$C23+1) -> 32 | E23: =INDEX($K$21:$Z$21,4*E$22+$C23+1) -> 88 | F23: =INDEX($K$21:$Z$21,4*F$22+$C23+1) -> 31 | G23: =INDEX($K$21:$Z$21,4*G$22+$C23+1) -> e0
C24: 1 | D24: =INDEX($K$21:$Z$21,4*D$22+$C24+1) -> 43 | E24: =INDEX($K$21:$Z$21,4*E$22+$C24+1) -> 5a | F24: =INDEX($K$21:$Z$21,4*F$22+$C24+1) -> 31 | G24: =INDEX($K$21:$Z$21,4*G$22+$C24+1) -> 37
C25: 2 | D25: =INDEX($K$21:$Z$21,4*D$22+$C25+1) -> f6 | E25: =INDEX($K$21:$Z$21,4*E$22+$C25+1) -> 30 | F25: =INDEX($K$21:$Z$21,4*F$22+$C25+1) -> 98 | G25: =INDEX($K$21:$Z$21,4*G$22+$C25+1) -> 07
C26: 3 | D26: =INDEX($K$21:$Z$21,4*D$22+$C26+1) -> a8 | E26: =INDEX($K$21:$Z$21,4*E$22+$C26+1) -> 8d | F26: =INDEX($K$21:$Z$21,4*F$22+$C26+1) -> a2 | G26: =INDEX($K$21:$Z$21,4*G$22+$C26+1) -> 34
B28: 2-1) 1라운드 암호키
D29: 0 | E29: 1 | F29: 2 | G29: 3 | I29: 바이트 단위 인덱스 | K29: 0 | L29: 1 | M29: 2 | N29: 3 | O29: 4 | P29: 5 | Q29: 6 | R29: 7 | S29: 8 | T29: 9 | U29: 10 | V29: 11 | W29: 12 | X29: 13 | Y29: 14 | Z29: 15
C30: 0 | D30: =INDEX($K$41:$Z$41,4*D$29+$C30+1) -> a0 | E30: =INDEX($K$41:$Z$41,4*E$29+$C30+1) -> 88 | F30: =INDEX($K$41:$Z$41,4*F$29+$C30+1) -> 23 | G30: =INDEX($K$41:$Z$41,4*G$29+$C30+1) -> 2a | H30: <- 값을 수식을 통해 | I30: 라운드 입력(Key) | K30: ='키생성과정(Key Scheduling)'!D10 -> 2b | L30: ='키생성과정(Key Scheduling)'!D11 -> 7e | M30: ='키생성과정(Key Scheduling)'!D12 -> 15 | N30: ='키생성과정(Key Scheduling)'!D13 -> 16 | O30: ='키생성과정(Key Scheduling)'!E10 -> 28 | P30: ='키생성과정(Key Scheduling)'!E11 -> ae | Q30: ='키생성과정(Key Scheduling)'!E12 -> d2 | R30: ='키생성과정(Key Scheduling)'!E13 -> a6 | S30: ='키생성과정(Key Scheduling)'!F10 -> ab | T30: ='키생성과정(Key Scheduling)'!F11 -> f7 | U30: ='키생성과정(Key Scheduling)'!F12 -> 15 | V30: ='키생성과정(Key Scheduling)'!F13 -> 88 | W30: ='키생성과정(Key Scheduling)'!G10 -> 09 | X30: ='키생성과정(Key Scheduling)'!G11 -> cf | Y30: ='키생성과정(Key Scheduling)'!G12 -> 4f | Z30: ='키생성과정(Key Scheduling)'!G13 -> 3c
C31: 1 | D31: =INDEX($K$41:$Z$41,4*D$29+$C31+1) -> fa | E31: =INDEX($K$41:$Z$41,4*E$29+$C31+1) -> 54 | F31: =INDEX($K$41:$Z$41,4*F$29+$C31+1) -> a3 | G31: =INDEX($K$41:$Z$41,4*G$29+$C31+1) -> 6c | H31: 출력하도록 작성 | I31: 1열 연산(Wi = SubBytes(RotWord(Wi-1))^Rcon^Wi-4)
C32: 2 | D32: =INDEX($K$41:$Z$41,4*D$29+$C32+1) -> fe | E32: =INDEX($K$41:$Z$41,4*E$29+$C32+1) -> 2c | F32: =INDEX($K$41:$Z$41,4*F$29+$C32+1) -> 39 | G32: =INDEX($K$41:$Z$41,4*G$29+$C32+1) -> 76 | I32: Wi-1 | K32: ='키생성과정(Key Scheduling)'!J13 -> 09 | L32: ='키생성과정(Key Scheduling)'!J10 -> cf | M32: ='키생성과정(Key Scheduling)'!J11 -> 4f | N32: ='키생성과정(Key Scheduling)'!J12 -> 3c
C33: 3 | D33: =INDEX($K$41:$Z$41,4*D$29+$C33+1) -> 17 | E33: =INDEX($K$41:$Z$41,4*E$29+$C33+1) -> b1 | F33: =INDEX($K$41:$Z$41,4*F$29+$C33+1) -> 39 | G33: =INDEX($K$41:$Z$41,4*G$29+$C33+1) -> 05 | I33: RotWord(Wi-1) | K33: ='키생성과정(Key Scheduling)'!J10 -> cf | L33: ='키생성과정(Key Scheduling)'!J11 -> 4f | M33: ='키생성과정(Key Scheduling)'!J12 -> 3c | N33: ='키생성과정(Key Scheduling)'!J13 -> 09
I34: SubBytes(RotWord(Wi-1) | K34: ='키생성과정(Key Scheduling)'!M10 -> 8a | L34: ='키생성과정(Key Scheduling)'!M11 -> 84 | M34: ='키생성과정(Key Scheduling)'!M12 -> eb | N34: ='키생성과정(Key Scheduling)'!M13 -> 01
I35: 라운드 Rcon | K35: ='키생성과정(Key Scheduling)'!P10 -> 01 | L35: ='키생성과정(Key Scheduling)'!P11 -> 00 | M35: ='키생성과정(Key Scheduling)'!P12 -> 00 | N35: ='키생성과정(Key Scheduling)'!P13 -> 00
I36: Wi-4 | K36: ='키생성과정(Key Scheduling)'!D10 -> 2b | L36: ='키생성과정(Key Scheduling)'!D11 -> 7e | M36: ='키생성과정(Key Scheduling)'!D12 -> 15 | N36: ='키생성과정(Key Scheduling)'!D13 -> 16
I37: 1연 연산(Wi) | K37: ='키생성과정(Key Scheduling)'!D17 -> a0 | L37: ='키생성과정(Key Scheduling)'!D18 -> fa | M37: ='키생성과정(Key Scheduling)'!D19 -> fe | N37: ='키생성과정(Key Scheduling)'!D20 -> 17
I38: 2열 연산(Wi = Wi-1^Wi-4) | K38: ='키생성과정(Key Scheduling)'!E17 -> 88 | L38: ='키생성과정(Key Scheduling)'!E18 -> 54 | M38: ='키생성과정(Key Scheduling)'!E19 -> 2c | N38: ='키생성과정(Key Scheduling)'!E20 -> b1
I39: 3열 연산(Wi = Wi-1^Wi-4) | K39: ='키생성과정(Key Scheduling)'!F17 -> 23 | L39: ='키생성과정(Key Scheduling)'!F18 -> a3 | M39: ='키생성과정(Key Scheduling)'!F19 -> 39 | N39: ='키생성과정(Key Scheduling)'!F20 -> 39
I40: 4열 연산(Wi = Wi-1^Wi-4) | K40: ='키생성과정(Key Scheduling)'!G17 -> 2a | L40: ='키생성과정(Key Scheduling)'!G18 -> 6c | M40: ='키생성과정(Key Scheduling)'!G19 -> 76 | N40: ='키생성과정(Key Scheduling)'!G20 -> 05
K41: ='키생성과정(Key Scheduling)'!D17 -> a0 | L41: ='키생성과정(Key Scheduling)'!D18 -> fa | M41: ='키생성과정(Key Scheduling)'!D19 -> fe | N41: ='키생성과정(Key Scheduling)'!D20 -> 17 | O41: ='키생성과정(Key Scheduling)'!E17 -> 88 | P41: ='키생성과정(Key Scheduling)'!E18 -> 54 | Q41: ='키생성과정(Key Scheduling)'!E19 -> 2c | R41: ='키생성과정(Key Scheduling)'!E20 -> b1 | S41: ='키생성과정(Key Scheduling)'!F17 -> 23 | T41: ='키생성과정(Key Scheduling)'!F18 -> a3 | U41: ='키생성과정(Key Scheduling)'!F19 -> 39 | V41: ='키생성과정(Key Scheduling)'!F20 -> 39 | W41: ='키생성과정(Key Scheduling)'!G17 -> 2a | X41: ='키생성과정(Key Scheduling)'!G18 -> 6c | Y41: ='키생성과정(Key Scheduling)'!G19 -> 76 | Z41: ='키생성과정(Key Scheduling)'!G20 -> 05
B42: 2-2) 2라운드 암호키
D43: 0 | E43: 1 | F43: 2 | G43: 3 | I43: 바이트 단위 인덱스 | K43: 0 | L43: 1 | M43: 2 | N43: 3 | O43: 4 | P43: 5 | Q43: 6 | R43: 7 | S43: 8 | T43: 9 | U43: 10 | V43: 11 | W43: 12 | X43: 13 | Y43: 14 | Z43: 15
C44: 0 | D44: =INDEX($K$55:$Z$55,4*D$43+$C44+1) -> f2 | E44: =INDEX($K$55:$Z$55,4*E$43+$C44+1) -> 7a | F44: =INDEX($K$55:$Z$55,4*F$43+$C44+1) -> 59 | G44: =INDEX($K$55:$Z$55,4*G$43+$C44+1) -> 73 | H44: <- 값을 수식을 통해 | I44: 라운드 입력(Key) | K44: ='키생성과정(Key Scheduling)'!D17 -> a0 | L44: ='키생성과정(Key Scheduling)'!D18 -> fa | M44: ='키생성과정(Key Scheduling)'!D19 -> fe | N44: ='키생성과정(Key Scheduling)'!D20 -> 17 | O44: ='키생성과정(Key Scheduling)'!E17 -> 88 | P44: ='키생성과정(Key Scheduling)'!E18 -> 54 | Q44: ='키생성과정(Key Scheduling)'!E19 -> 2c | R44: ='키생성과정(Key Scheduling)'!E20 -> b1 | S44: ='키생성과정(Key Scheduling)'!F17 -> 23 | T44: ='키생성과정(Key Scheduling)'!F18 -> a3 | U44: ='키생성과정(Key Scheduling)'!F19 -> 39 | V44: ='키생성과정(Key Scheduling)'!F20 -> 39 | W44: ='키생성과정(Key Scheduling)'!G17 -> 2a | X44: ='키생성과정(Key Scheduling)'!G18 -> 6c | Y44: ='키생성과정(Key Scheduling)'!G19 -> 76 | Z44: ='키생성과정(Key Scheduling)'!G20 -> 05
C45: 1 | D45: =INDEX($K$55:$Z$55,4*D$43+$C45+1) -> c2 | E45: =INDEX($K$55:$Z$55,4*E$43+$C45+1) -> 96 | F45: =INDEX($K$55:$Z$55,4*F$43+$C45+1) -> 35 | G45: =INDEX($K$55:$Z$55,4*G$43+$C45+1) -> 59 | H45: 출력하도록 작성 | I45: 1열 연산(Wi = SubBytes(RotWord(Wi-1))^Rcon^Wi-4)
...

Sheet 키생성과정(Key Scheduling)
B2: *1 AES 키 생성 과정
B3: DES_암호화_과정.xlxs 파일을 참고하여 최대한 세분화 단계로 나눠 표현
B4: 각 단계별 주석을 붙이고, 계산식을 활용하여 자동 계산할 수 있도록 함
B5: 일부 연산과정이 계산식 활용이 어려운 경우, 임의로 값을 기입하여 완성
C7: 1라운드 암호키
C8: Cipher key | I8: RotWord | L8: SubBytes | O8: Rcon
D9: 0 | E9: 1 | F9: 2 | G9: 3 | J9: 0 | M9: 0 | P9: 0 | Q9: 1 | R9: 2 | S9: 3 | T9: 4 | U9: 5 | V9: 6 | W9: 7 | X9: 8 | Y9: 9
C10: 0 | D10: =종합!K10 -> 2b | E10: =종합!O10 -> 28 | F10: =종합!S10 -> ab | G10: =종합!W10 -> 09 | I10: 0 | J10: =종합!X10 -> cf | L10: 0 | M10: {=INDEX('S-box'!$D$5:$S$20,HEX2DEC(LEFT(J10,1))+1, HEX2DEC(RIGHT(J10,1))+1)} -> 8a | O10: 0 | P10: 01 | Q10: 02 | R10: 04 | S10: 08 | T10: 10 | U10: 20 | V10: 40 | W10: 80 | X10: 1b | Y10: 36
C11: 1 | D11: =종합!L10 -> 7e | E11: =종합!P10 -> ae | F11: =종합!T10 -> f7 | G11: =종합!X10 -> cf | I11: 1 | J11: =종합!Y10 -> 4f | L11: 1 | M11: {=INDEX('S-box'!$D$5:$S$20,HEX2DEC(LEFT(J11,1))+1, HEX2DEC(RIGHT(J11,1))+1)} -> 84 | O11: 1 | P11: 00 | Q11: 00 | R11: 00 | S11: 00 | T11: 00 | U11: 00 | V11: 00 | W11: 00 | X11: 00 | Y11: 00
C12: 2 | D12: =종합!M10 -> 15 | E12: =종합!Q10 -> d2 | F12: =종합!U10 -> 15 | G12: =종합!Y10 -> 4f | I12: 2 | J12: =종합!Z10 -> 3c | L12: 2 | M12: {=INDEX('S-box'!$D$5:$S$20,HEX2DEC(LEFT(J12,1))+1, HEX2DEC(RIGHT(J12,1))+1)} -> eb | O12: 2 | P12: 00 | Q12: 00 | R12: 00 | S12: 00 | T12: 00 | U12: 00 | V12: 00 | W12: 00 | X12: 00 | Y12: 00
C13: 3 | D13: =종합!N10 -> 16 | E13: =종합!R10 -> a6 | F13: =종합!V10 -> 88 | G13: =종합!Z10 -> 3c | I13: 3 | J13: =종합!W10 -> 09 | L13: 3 | M13: {=INDEX('S-box'!$D$5:$S$20,HEX2DEC(LEFT(J13,1))+1, HEX2DEC(RIGHT(J13,1))+1)} -> 01 | O13: 3 | P13: 00 | Q13: 00 | R13: 00 | S13: 00 | T13: 00 | U13: 00 | V13: 00 | W13: 00 | X13: 00 | Y13: 00
C15: RoundKey1
D16: 0 | E16: 1 | F16: 2 | G16: 3 | J16: 1. RotWord : 이전 열(Wi-1)을 가져와서 위로 회전 시프트
C17: 0 | D17: =LOWER(DEC2HEX(_xlfn.BITXOR(_xlfn.BITXOR(HEX2DEC(D10),HEX2DEC(M10)),HEX2DEC($P10)))) -> a0 | E17: =LOWER(DEC2HEX(_xlfn.BITXOR(HEX2DEC(E10), HEX2DEC(D17)))) -> 88 | F17: =LOWER(DEC2HEX(_xlfn.BITXOR(HEX2DEC(F10), HEX2DEC(E17)))) -> 23 | G17: =LOWER(DEC2HEX(_xlfn.BITXOR(HEX2DEC(G10), HEX2DEC(F17)))) -> 2a | J17: 2. HEX2DEC() 함수를 통해 10진수로 변환 후 S-box에 있는 데이터를 가져온다.
C18: 1 | D18: =LOWER(DEC2HEX(_xlfn.BITXOR(_xlfn.BITXOR(HEX2DEC(D11),HEX2DEC(M11)),HEX2DEC($P11)))) -> fa | E18: =LOWER(DEC2HEX(_xlfn.BITXOR(HEX2DEC(E11), HEX2DEC(D18)))) -> 54 | F18: =LOWER(DEC2HEX(_xlfn.BITXOR(HEX2DEC(F11), HEX2DEC(E18)))) -> a3 | G18: =LOWER(DEC2HEX(_xlfn.BITXOR(HEX2DEC(G11), HEX2DEC(F18)))) -> 6c | J18: 3. HEX2DEC() 함수를 통해 10진수로 변환 후 Rcon과 나머지 열 들을 BITXOR() 함수로 XOR을 한 뒤
C19: 2 | D19: =LOWER(DEC2HEX(_xlfn.BITXOR(_xlfn.BITXOR(HEX2DEC(D12),HEX2DEC(M12)),HEX2DEC($P12)))) -> fe | E19: =LOWER(DEC2HEX(_xlfn.BITXOR(HEX2DEC(E12), HEX2DEC(D19)))) -> 2c | F19: =LOWER(DEC2HEX(_xlfn.BITXOR(HEX2DEC(F12), HEX2DEC(E19)))) -> 39 | G19: =LOWER(DEC2HEX(_xlfn.BITXOR(HEX2DEC(G12), HEX2DEC(F19)))) -> 76 | J19: DEC2HEX() 함수로 16진수로 변환하고, LOWER() 함수로 소문자로 바꿔준다.
C20: 3 | D20: =LOWER(DEC2HEX(_xlfn.BITXOR(_xlfn.BITXOR(HEX2DEC(D13),HEX2DEC(M13)),HEX2DEC($P13)))) -> 17 | E20: =LOWER(DEC2HEX(_xlfn.BITXOR(HEX2DEC(E13), HEX2DEC(D20)))) -> b1 | F20: =LOWER(DEC2HEX(_xlfn.BITXOR(HEX2DEC(F13), HEX2DEC(E20)))) -> 39 | G20: =LOWER(TEXT(DEC2HEX(_xlfn.BITXOR(HEX2DEC(G13), HEX2DEC(F20))), "00")) -> 05
C22: 2라운드 암호키
C23: RotWord | G23: SubBytes | K23: Rcon | N23: RoundKey1
D24: 0 | H24: 0 | L24: 0 | O24: 0 | P24: 1 | Q24: 2 | R24: 3
C25: 0 | D25: =G18 -> 6c | G25: 0 | H25: {=INDEX('S-box'!$D$5:$S$20,HEX2DEC(LEFT(D25,1))+1, HEX2DEC(RIGHT(D25,1))+1)} -> 50 | K25: 0 | L25: 02 | N25: 0 | O25: =LOWER(DEC2HEX(_xlfn.BITXOR(_xlfn.BITXOR(HEX2DEC(D17),HEX2DEC(H25)),HEX2DEC($L25)))) -> f2 | P25: =LOWER(DEC2HEX(_xlfn.BITXOR(HEX2DEC(E17), HEX2DEC(O25)))) -> 7a | Q25: =LOWER(DEC2HEX(_xlfn.BITXOR(HEX2DEC(F17), HEX2DEC(P25)))) -> 59 | R25: =LOWER(DEC2HEX(_xlfn.BITXOR(HEX2DEC(G17), HEX2DEC(Q25)))) -> 73
C26: 1 | D26: =G19 -> 76 | G26: 1 | H26: {=INDEX('S-box'!$D$5:$S$20,HEX2DEC(LEFT(D26,1))+1, HEX2DEC(RIGHT(D26,1))+1)} -> 38 | K26: 1 | L26: 00 | N26: 1 | O26: =LOWER(DEC2HEX(_xlfn.BITXOR(_xlfn.BITXOR(HEX2DEC(D18),HEX2DEC(H26)),HEX2DEC($L26)))) -> c2 | P26: =LOWER(DEC2HEX(_xlfn.BITXOR(HEX2DEC(E18), HEX2DEC(O26)))) -> 96 | Q26: =LOWER(DEC2HEX(_xlfn.BITXOR(HEX2DEC(F18), HEX2DEC(P26)))) -> 35 | R26: =LOWER(DEC2HEX(_xlfn.BITXOR(HEX2DEC(G18), HEX2DEC(Q26)))) -> 59
C27: 2 | D27: =G20 -> 05 | G27: 2 | H27: {=INDEX('S-box'!$D$5:$S$20,HEX2DEC(LEFT(D27,1))+1, HEX2DEC(RIGHT(D27,1))+1)} -> 6b | K27: 2 | L27: 00 | N27: 2 | O27: =LOWER(DEC2HEX(_xlfn.BITXOR(_xlfn.BITXOR(HEX2DEC(D19),HEX2DEC(H27)),HEX2DEC($L27)))) -> 95 | P27: =LOWER(DEC2HEX(_xlfn.BITXOR(HEX2DEC(E19), HEX2DEC(O27)))) -> b9 | Q27: =LOWER(DEC2HEX(_xlfn.BITXOR(HEX2DEC(F19), HEX2DEC(P27)))) -> 80 | R27: =LOWER(DEC2HEX(_xlfn.BITXOR(HEX2DEC(G19), HEX2DEC(Q27)))) -> f6
C28: 3 | D28: =G17 -> 2a | G28: 3 | H28: {=INDEX('S-box'!$D$5:$S$20,HEX2DEC(LEFT(D28,1))+1, HEX2DEC(RIGHT(D28,1))+1)} -> e5 | K28: 3 | L28: 00 | N28: 3 | O28: =LOWER(DEC2HEX(_xlfn.BITXOR(_xlfn.BITXOR(HEX2DEC(D20),HEX2DEC(H28)),HEX2DEC($L28)))) -> f2 | P28: =LOWER(DEC2HEX(_xlfn.BITXOR(HEX2DEC(E20), HEX2DEC(O28)))) -> 43 | Q28: =LOWER(DEC2HEX(_xlfn.BITXOR(HEX2DEC(F20), HEX2DEC(P28)))) -> 7a | R28: =LOWER(DEC2HEX(_xlfn.BITXOR(HEX2DEC(G20), HEX2DEC(Q28)))) -> 7f

Sheet 암호화과정(Ciphering)
B2: *2 AES 암호화 과정
B3: DES_암호화_과정.xlxs 파일을 참고하여 최대한 세분화 단계로 나눠 표현
B4: 각 단계별 주석을 붙이고, 계산식을 활용하여 자동 계산할 수 있도록 함
B5: 일부 연산과정이 계산식 활용이 어려운 경우, 임의로 값을 기입하여 완성
C7: 1라운드 AES 계산 입력
C8: 평문 | I8: 암호문 | O8: After AddRoundKey
D9: 0 | E9: 1 | F9: 2 | G9: 3 | J9: 0 | K9: 1 | L9: 2 | M9: 3 | P9: 0 | Q9: 1 | R9: 2 | S9: 3 | U9: 1. HEX2DEC() 함수를 통해 10진수로 변환 후 평문과 암호문을 BITXOR() 함수로 XOR을 한 뒤,
C10: 0 | D10: =INDEX($K$21:$T$21,4*C$22+$D10+1) -> 32 | E10: =INDEX($K$21:$T$21,4*D$22+$D10+1) -> 88 | F10: =INDEX($K$21:$T$21,4*E$22+$D10+1) -> 31 | G10: =INDEX($K$21:$T$21,4*F$22+$D10+1) -> e0 | I10: 0 | J10: =INDEX($K$10:$Z$10,4*J$12+$C10+1) -> 2b | K10: =INDEX($K$10:$Z$10,4*K$12+$C10+1) -> 28 | L10: =INDEX($K$10:$Z$10,4*L$12+$C10+1) -> ab | M10: =INDEX($K$10:$Z$10,4*M$12+$C10+1) -> 09 | O10: 0 | P10: =LOWER(DEC2HEX(_xlfn.BITXOR(HEX2DEC(D10),HEX2DEC(J10)))) -> 19 | Q10: =LOWER(DEC2HEX(_xlfn.BITXOR(HEX2DEC(E10),HEX2DEC(K10)))) -> a0 | R10: =LOWER(DEC2HEX(_xlfn.BITXOR(HEX2DEC(F10),HEX2DEC(L10)))) -> 9a | S10: =LOWER(DEC2HEX(_xlfn.BITXOR(HEX2DEC(G10),HEX2DEC(M10)))) -> e9 | U10: DEC2HEX() 함수로 16진수로 변환하고, LOWER() 함수로 소문자로 바꿔준다.
C11: 1 | D11: =INDEX($K$21:$T$21,4*C$22+$D11+1) -> 43 | E11: =INDEX($K$21:$T$21,4*D$22+$D11+1) -> 5a | F11: =INDEX($K$21:$T$21,4*E$22+$D11+1) -> 31 | G11: =INDEX($K$21:$T$21,4*F$22+$D11+1) -> 37 | I11: 1 | J11: =INDEX($K$10:$Z$10,4*J$12+$C11+1) -> 7e | K11: =INDEX($K$10:$Z$10,4*K$12+$C11+1) -> ae | L11: =INDEX($K$10:$Z$10,4*L$12+$C11+1) -> f7 | M11: =INDEX($K$10:$Z$10,4*M$12+$C11+1) -> cf | O11: 1 | P11: =LOWER(DEC2HEX(_xlfn.BITXOR(HEX2DEC(D11),HEX2DEC(J11)))) -> 3d | Q11: =LOWER(DEC2HEX(_xlfn.BITXOR(HEX2DEC(E11),HEX2DEC(K11)))) -> f4 | R11: =LOWER(DEC2HEX(_xlfn.BITXOR(HEX2DEC(F11),HEX2DEC(L11)))) -> c6 | S11: =LOWER(DEC2HEX(_xlfn.BITXOR(HEX2DEC(G11),HEX2DEC(M11)))) -> f8
C12: 2 | D12: =INDEX($K$21:$T$21,4*C$22+$D12+1) -> f6 | E12: =INDEX($K$21:$T$21,4*D$22+$D12+1) -> 30 | F12: =INDEX($K$21:$T$21,4*E$22+$D12+1) -> 98 | G12: =INDEX($K$21:$T$21,4*F$22+$D12+1) -> 07 | I12: 2 | J12: =INDEX($K$10:$Z$10,4*J$12+$C12+1) -> 15 | K12: =INDEX($K$10:$Z$10,4*K$12+$C12+1) -> d2 | L12: =INDEX($K$10:$Z$10,4*L$12+$C12+1) -> 15 | M12: =INDEX($K$10:$Z$10,4*M$12+$C12+1) -> 4f | O12: 2 | P12: =LOWER(DEC2HEX(_xlfn.BITXOR(HEX2DEC(D12),HEX2DEC(J12)))) -> e3 | Q12: =LOWER(DEC2HEX(_xlfn.BITXOR(HEX2DEC(E12),HEX2DEC(K12)))) -> e2 | R12: =LOWER(DEC2HEX(_xlfn.BITXOR(HEX2DEC(F12),HEX2DEC(L12)))) -> 8d | S12: =LOWER(DEC2HEX(_xlfn.BITXOR(HEX2DEC(G12),HEX2DEC(M12)))) -> 48
C13: 3 | D13: =INDEX($K$21:$T$21,4*C$22+$D13+1) -> a8 | E13: =INDEX($K$21:$T$21,4*D$22+$D13+1) -> 8d | F13: =INDEX($K$21:$T$21,4*E$22+$D13+1) -> a2 | G13: =INDEX($K$21:$T$21,4*F$22+$D13+1) -> 34 | I13: 3 | J13: =INDEX($K$10:$Z$10,4*J$12+$C13+1) -> 16 | K13: =INDEX($K$10:$Z$10,4*K$12+$C13+1) -> a6 | L13: =INDEX($K$10:$Z$10,4*L$12+$C13+1) -> 88 | M13: =INDEX($K$10:$Z$10,4*M$12+$C13+1) -> 3c | O13: 3 | P13: =LOWER(DEC2HEX(_xlfn.BITXOR(HEX2DEC(D13),HEX2DEC(J13)))) -> be | Q13: =LOWER(DEC2HEX(_xlfn.BITXOR(HEX2DEC(E13),HEX2DEC(K13)))) -> 2b | R13: =LOWER(DEC2HEX(_xlfn.BITXOR(HEX2DEC(F13),HEX2DEC(L13)))) -> 2a | S13: =LOWER(TEXT(DEC2HEX(_xlfn.BITXOR(HEX2DEC(G13), HEX2DEC(M13))), "00")) -> 08
C15: 1라운드 AES 계산 결과 (=2라운드 AES 계산 입력)
C16: After SubBytes | I16: After ShiftRows | O16: After MixColumns | U16: MixColumns Round1 | AO16: MixColumns Round2
D17: 0 | E17: 1 | F17: 2 | G17: 3 | J17: 0 | K17: 1 | L17: 2 | M17: 3 | P17: 0 | Q17: 1 | R17: 2 | S17: 3 | U17: 0 | V17: 1 | W17: 2 | X17: 3 | Z17: 4 | AA17: 5 | AB17: 6 | AC17: 7 | AE17: 8 | AF17: 9 | AG17: 10 | AH17: 11 | AJ17: 12 | AK17: 13 | AL17: 14 | AM17: 15 | AO17: 0 | AP17: 1 | AQ17: 2 | AR17: 3 | AT17: 4 | AU17: 5 | AV17: 6 | AW17: 7 | AY17: 8 | AZ17: 9 | BA17: 10 | BB17: 11 | BD17: 12 | BE17: 13 | BF17: 14 | BG17: 15
C18: 0 | D18: {=INDEX('S-box'!$D$5:$S$20,HEX2DEC(LEFT(P10,1))+1, HEX2DEC(RIGHT(P10,1))+1)} -> d4 | E18: {=INDEX('S-box'!$D$5:$S$20,HEX2DEC(LEFT(Q10,1))+1, HEX2DEC(RIGHT(Q10,1))+1)} -> e0 | F18: {=INDEX('S-box'!$D$5:$S$20,HEX2DEC(LEFT(R10,1))+1, HEX2DEC(RIGHT(R10,1))+1)} -> b8 | G18: {=INDEX('S-box'!$D$5:$S$20,HEX2DEC(LEFT(S10,1))+1, HEX2DEC(RIGHT(S10,1))+1)} -> 1e | I18: 0 | J18: =D18 -> d4 | K18: =E18 -> e0 | L18: =F18 -> b8 | M18: =G18 -> 1e | O18: 0 | P18: =U26 -> 04 | Q18: =Z26 -> e0 | R18: =AE26 -> 48 | S18: =AJ26 -> 28 | U18: =$J$18 -> d4 | V18: =$J$19 -> bf | W18: =$J$20 -> 5d | X18: =$J$21 -> 30 | Z18: =$K$18 -> e0 | AA18: =$K$19 -> b4 | AB18: =$K$20 -> 52 | AC18: =$K$21 -> ae | AE18: =$L$18 -> b8 | AF18: =$L$19 -> 41 | AG18: =$L$20 -> 11 | AH18: =$L$21 -> f1 | AJ18: =$M$18 -> 1e | AK18: =$M$19 -> 27 | AL18: =$M$20 -> 98 | AM18: =$M$21 -> e5 | AO18: =$J$33 -> 49 | AP18: =$J$34 -> db | AQ18: =$J$35 -> 87 | AR18: =$J$36 -> 3b | AT18: =$K$33 -> 45 | AU18: =$K$34 -> 39 | AV18: =$K$35 -> 53 | AW18: =$K$36 -> 89 | AY18: =$L$33 -> 7f | AZ18: =$L$34 -> 02 | BA18: =$L$35 -> d2 | BB18: =$L$36 -> f1 | BD18: =$M$33 -> 77 | BE18: =$M$34 -> de | BF18: =$M$35 -> 96 | BG18: =$M$36 -> 1a
C19: 1 | D19: {=INDEX('S-box'!$D$5:$S$20,HEX2DEC(LEFT(P11,1))+1, HEX2DEC(RIGHT(P11,1))+1)} -> 27 | E19: {=INDEX('S-box'!$D$5:$S$20,HEX2DEC(LEFT(Q11,1))+1, HEX2DEC(RIGHT(Q11,1))+1)} -> bf | F19: {=INDEX('S-box'!$D$5:$S$20,HEX2DEC(LEFT(R11,1))+1, HEX2DEC(RIGHT(R11,1))+1)} -> b4 | G19: {=INDEX('S-box'!$D$5:$S$20,HEX2DEC(LEFT(S11,1))+1, HEX2DEC(RIGHT(S11,1))+1)} -> 41 | I19: 1 | J19: =E19 -> bf | K19: =F19 -> b4 | L19: =G19 -> 41 | M19: =D19 -> 27 | O19: 1 | P19: =V35 -> 66 | Q19: =AA35 -> cb | R19: =AF35 -> f8 | S19: =AK35 -> 06 | U19: =U18 -> d4 | Z19: =Z18 -> e0 | AE19: =AE18 -> b8 | AJ19: =AJ18 -> 1e | AO19: =AO18 -> 49 | AT19: =AT18 -> 45 | AY19: =AY18 -> 7f | BD19: =BD18 -> 77
C20: 2 | D20: {=INDEX('S-box'!$D$5:$S$20,HEX2DEC(LEFT(P12,1))+1, HEX2DEC(RIGHT(P12,1))+1)} -> 11 | E20: {=INDEX('S-box'!$D$5:$S$20,HEX2DEC(LEFT(Q12,1))+1, HEX2DEC(RIGHT(Q12,1))+1)} -> 98 | F20: {=INDEX('S-box'!$D$5:$S$20,HEX2DEC(LEFT(R12,1))+1, HEX2DEC(RIGHT(R12,1))+1)} -> 5d | G20: {=INDEX('S-box'!$D$5:$S$20,HEX2DEC(LEFT(S12,1))+1, HEX2DEC(RIGHT(S12,1))+1)} -> 52 | I20: 2 | J20: =F20 -> 5d | K20: =G20 -> 52 | L20: =D20 -> 11 | M20: =E20 -> 98 | O20: 2 | P20: =W44 -> 81 | Q20: =AB44 -> 19 | R20: =AG44 -> d3 | S20: =AL44 -> 26 | U20: =IF(HEX2DEC(U19)>127,DEC2HEX(_xlfn.BITXOR(_xlfn.BITLSHIFT(HEX2DEC(U19)-128,1),HEX2DEC("1B"))),DEC2HEX(_xlfn.BITLSHIFT(HEX2DEC(U19),1))) -> B3 | Z20: =IF(HEX2DEC(Z19)>127,DEC2HEX(_xlfn.BITXOR(_xlfn.BITLSHIFT(HEX2DEC(Z19)-128,1),HEX2DEC("1B"))),DEC2HEX(_xlfn.BITLSHIFT(HEX2DEC(Z19),1))) -> DB | AE20: =IF(HEX2DEC(AE19)>127,DEC2HEX(_xlfn.BITXOR(_xlfn.BITLSHIFT(HEX2DEC(AE19)-128,1),HEX2DEC("1B"))),DEC2HEX(_xlfn.BITLSHIFT(HEX2DEC(AE19),1))) -> 6B | AJ20: =IF(HEX2DEC(AJ19)>127,DEC2HEX(_xlfn.BITXOR(_xlfn.BITLSHIFT(HEX2DEC(AJ19)-128,1),HEX2DEC("1B"))),DEC2HEX(_xlfn.BITLSHIFT(HEX2DEC(AJ19),1))) -> 3C | AO20: =IF(HEX2DEC(AO19)>127,DEC2HEX(_xlfn.BITXOR(_xlfn.BITLSHIFT(HEX2DEC(AO19)-128,1),HEX2DEC("1B"))),DEC2HEX(_xlfn.BITLSHIFT(HEX2DEC(AO19),1))) -> 92 | AT20: =IF(HEX2DEC(AT19)>127,DEC2HEX(_xlfn.BITXOR(_xlfn.BITLSHIFT(HEX2DEC(AT19)-128,1),HEX2DEC("1B"))),DEC2HEX(_xlfn.BITLSHIFT(HEX2DEC(AT19),1))) -> 8A | AY20: =IF(HEX2DEC(AY19)>127,DEC2HEX(_xlfn.BITXOR(_xlfn.BITLSHIFT(HEX2DEC(AY19)-128,1),HEX2DEC("1B"))),DEC2HEX(_xlfn.BITLSHIFT(HEX2DEC(AY19),1))) -> FE | BD20: =IF(HEX2DEC(BD19)>127,DEC2HEX(_xlfn.BITXOR(_xlfn.BITLSHIFT(HEX2DEC(BD19)-128,1),HEX2DEC("1B"))),DEC2HEX(_xlfn.BITLSHIFT(HEX2DEC(BD19),1))) -> EE
C21: 3 | D21: {=INDEX('S-box'!$D$5:$S$20,HEX2DEC(LEFT(P13,1))+1, HEX2DEC(RIGHT(P13,1))+1)} -> ae | E21: {=INDEX('S-box'!$D$5:$S$20,HEX2DEC(LEFT(Q13,1))+1, HEX2DEC(RIGHT(Q13,1))+1)} -> f1 | F21: {=INDEX('S-box'!$D$5:$S$20,HEX2DEC(LEFT(R13,1))+1, HEX2DEC(RIGHT(R13,1))+1)} -> e5 | G21: {=INDEX('S-box'!$D$5:$S$20,HEX2DEC(LEFT(S13,1))+1, HEX2DEC(RIGHT(S13,1))+1)} -> 30 | I21: 3 | J21: =G21 -> 30 | K21: =D21 -> ae | L21: =E21 -> f1 | M21: =F21 -> e5 | O21: 3 | P21: =X53 -> e5 | Q21: =AC53 -> 9a | R21: =AH53 -> 7a | S21: =AM53 -> 4c | V21: =V18 -> bf | AA21: =AA18 -> b4 | AF21: =AF18 -> 41 | AK21: =AK18 -> 27 | AP21: =AP18 -> db | AU21: =AU18 -> 39 | AZ21: =AZ18 -> 02 | BE21: =BE18 -> de
V22: =IF(HEX2DEC(V21)>127,DEC2HEX(_xlfn.BITXOR(_xlfn.BITLSHIFT(HEX2DEC(V21)-128,1),HEX2DEC("1B"))),DEC2HEX(_xlfn.BITLSHIFT(HEX2DEC(V21),1))) -> 65 | AA22: =IF(HEX2DEC(AA21)>127,DEC2HEX(_xlfn.BITXOR(_xlfn.BITLSHIFT(HEX2DEC(AA21)-128,1),HEX2DEC("1B"))),DEC2HEX(_xlfn.BITLSHIFT(HEX2DEC(AA21),1))) -> 73 | AF22: =IF(HEX2DEC(AF21)>127,DEC2HEX(_xlfn.BITXOR(_xlfn.BITLSHIFT(HEX2DEC(AF21)-128,1),HEX2DEC("1B"))),DEC2HEX(_xlfn.BITLSHIFT(HEX2DEC(AF21),1))) -> 82 | AK22: =IF(HEX2DEC(AK21)>127,DEC2HEX(_xlfn.BITXOR(_xlfn.BITLSHIFT(HEX2DEC(AK21)-128,1),HEX2DEC("1B"))),DEC2HEX(_xlfn.BITLSHIFT(HEX2DEC(AK21),1))) -> 4E | AP22: =IF(HEX2DEC(AP21)>127,DEC2HEX(_xlfn.BITXOR(_xlfn.BITLSHIFT(HEX2DEC(AP21)-128,1),HEX2DEC("1B"))),DEC2HEX(_xlfn.BITLSHIFT(HEX2DEC(AP21),1))) -> AD | AU22: =IF(HEX2DEC(AU21)>127,DEC2HEX(_xlfn.BITXOR(_xlfn.BITLSHIFT(HEX2DEC(AU21)-128,1),HEX2DEC("1B"))),DEC2HEX(_xlfn.BITLSHIFT(HEX2DEC(AU21),1))) -> 72 | AZ22: =IF(HEX2DEC(AZ21)>127,DEC2HEX(_xlfn.BITXOR(_xlfn.BITLSHIFT(HEX2DEC(AZ21)-128,1),HEX2DEC("1B"))),DEC2HEX(_xlfn.BITLSHIFT(HEX2DEC(AZ21),1))) -> 4 | BE22: =IF(HEX2DEC(BE21)>127,DEC2HEX(_xlfn.BITXOR(_xlfn.BITLSHIFT(HEX2DEC(BE21)-128,1),HEX2DEC("1B"))),DEC2HEX(_xlfn.BITLSHIFT(HEX2DEC(BE21),1))) -> A7
C23: Round key | I23: After AddRoundKey | V23: =DEC2HEX(_xlfn.BITXOR(HEX2DEC(V21),HEX2DEC(V22))) -> DA | AA23: =DEC2HEX(_xlfn.BITXOR(HEX2DEC(AA21),HEX2DEC(AA22))) -> C7 | AF23: =DEC2HEX(_xlfn.BITXOR(HEX2DEC(AF21),HEX2DEC(AF22))) -> C3 | AK23: =DEC2HEX(_xlfn.BITXOR(HEX2DEC(AK21),HEX2DEC(AK22))) -> 69 | AP23: =DEC2HEX(_xlfn.BITXOR(HEX2DEC(AP21),HEX2DEC(AP22))) -> 76 | AU23: =DEC2HEX(_xlfn.BITXOR(HEX2DEC(AU21),HEX2DEC(AU22))) -> 4B | AZ23: =DEC2HEX(_xlfn.BITXOR(HEX2DEC(AZ21),HEX2DEC(AZ22))) -> 6 | BE23: =DEC2HEX(_xlfn.BITXOR(HEX2DEC(BE21),HEX2DEC(BE22))) -> 79
D24: 0 | E24: 1 | F24: 2 | G24: 3 | J24: 0 | K24: 1 | L24: 2 | M24: 3 | W24: =W18 -> 5d | AB24: =AB18 -> 52 | AG24: =AG18 -> 11 | AL24: =AL18 -> 98 | AQ24: =AQ18 -> 87 | AV24: =AV18 -> 53 | BA24: =BA18 -> d2 | BF24: =BF18 -> 96
C25: 0 | D25: ='키생성과정(Key Scheduling)'!D17 -> a0 | E25: ='키생성과정(Key Scheduling)'!E17 -> 88 | F25: ='키생성과정(Key Scheduling)'!F17 -> 23 | G25: ='키생성과정(Key Scheduling)'!G17 -> 2a | I25: 0 | J25: =LOWER(DEC2HEX(_xlfn.BITXOR(HEX2DEC(P18),HEX2DEC(D25)))) -> a4 | K25: =LOWER(DEC2HEX(_xlfn.BITXOR(HEX2DEC(Q18),HEX2DEC(E25)))) -> 68 | L25: =LOWER(DEC2HEX(_xlfn.BITXOR(HEX2DEC(R18),HEX2DEC(F25)))) -> 6b | M25: =IF(LEN(DEC2HEX(_xlfn.BITXOR(HEX2DEC(S18),HEX2DEC(G25))))=1, "0"&DEC2HEX(_xlfn.BITXOR(HEX2DEC(S18),HEX2DEC(G25))), DEC2HEX(_xlfn.BITXOR(HEX2DEC(S18),HEX2DEC(G25)))) -> 02 | X25: =X18 -> 30 | AC25: =AC18 -> ae | AH25: =AH18 -> f1 | AM25: =AM18 -> e5 | AR25: =AR18 -> 3b | AW25: =AW18 -> 89 | BB25: =BB18 -> f1 | BG25: =BG18 -> 1a
C26: 1 | D26: ='키생성과정(Key Scheduling)'!D18 -> fa | E26: ='키생성과정(Key Scheduling)'!E18 -> 54 | F26: ='키생성과정(Key Scheduling)'!F18 -> a3 | G26: ='키생성과정(Key Scheduling)'!G18 -> 6c | I26: 1 | J26: =LOWER(DEC2HEX(_xlfn.BITXOR(HEX2DEC(P19),HEX2DEC(D26)))) -> 9c | K26: =LOWER(DEC2HEX(_xlfn.BITXOR(HEX2DEC(Q19),HEX2DEC(E26)))) -> 9f | L26: =LOWER(DEC2HEX(_xlfn.BITXOR(HEX2DEC(R19),HEX2DEC(F26)))) -> 5b | M26: =LOWER(DEC2HEX(_xlfn.BITXOR(HEX2DEC(S19),HEX2DEC(G26)))) -> 6a | U26: =IF(LEN(DEC2HEX(_xlfn.BITXOR(_xlfn.BITXOR(_xlfn.BITXOR(HEX2DEC(U$20),HEX2DEC(V$23)),HEX2DEC(W$24)),HEX2DEC(X$25))))=1, "0"&DEC2HEX(_xlfn.BITXOR(_xlfn.BITXOR(_xlfn.BITXOR(HEX2DEC(U$20),HEX2DEC(V$23)),HEX2DEC(W$24)),HEX2DEC(X$25))), DEC2HEX(_xlfn.BITXOR(_xlfn.BITXOR(_xlfn.BITXOR(HEX2DEC(U$20),HEX2DEC(V$23)),HEX2DEC(W$24)),HEX2DEC(X$25)))) -> 04 | Z26: =LOWER(DEC2HEX(_xlfn.BITXOR(_xlfn.BITXOR(_xlfn.BITXOR(HEX2DEC(Z20),HEX2DEC(AA23)),HEX2DEC(AB24)),HEX2DEC(AC25)))) -> e0 | AE26: =DEC2HEX(_xlfn.BITXOR(_xlfn.BITXOR(_xlfn.BITXOR(HEX2DEC(AE20),HEX2DEC(AF23)),HEX2DEC(AG24)),HEX2DEC(AH25))) -> 48 | AJ26: =DEC2HEX(_xlfn.BITXOR(_xlfn.BITXOR(_xlfn.BITXOR(HEX2DEC(AJ20),HEX2DEC(AK23)),HEX2DEC(AL24)),HEX2DEC(AM25))) -> 28 | AO26: =IF(LEN(DEC2HEX(_xlfn.BITXOR(_xlfn.BITXOR(_xlfn.BITXOR(HEX2DEC(AO$20),HEX2DEC(AP$23)),HEX2DEC(AQ$24)),HEX2DEC(AR$25))))=1, "0"&DEC2HEX(_xlfn.BITXOR(_xlfn.BITXOR(_xlfn.BITXOR(HEX2DEC(AO$20),HEX2DEC(AP$23)),HEX2DEC(AQ$24)),HEX2DEC(AR$25))), DEC2HEX(_xlfn.BITXOR(_xlfn.BITXOR(_xlfn.BITXOR(HEX2DEC(AO$20),HEX2DEC(AP$23)),HEX2DEC(AQ$24)),HEX2DEC(AR$25)))) -> 58 | AT26: =LOWER(DEC2HEX(_xlfn.BITXOR(_xlfn.BITXOR(_xlfn.BITXOR(HEX2DEC(AT20),HEX2DEC(AU23)),HEX2DEC(AV24)),HEX2DEC(AW25)))) -> 1b | AY26: =LOWER(DEC2HEX(_xlfn.BITXOR(_xlfn.BITXOR(_xlfn.BITXOR(HEX2DEC(AY20),HEX2DEC(AZ23)),HEX2DEC(BA24)),HEX2DEC(BB25)))) -> db | BD26: =DEC2HEX(_xlfn.BITXOR(_xlfn.BITXOR(_xlfn.BITXOR(HEX2DEC(BD20),HEX2DEC(BE23)),HEX2DEC(BF24)),HEX2DEC(BG25))) -> 1B
C27: 2 | D27: ='키생성과정(Key Scheduling)'!D19 -> fe | E27: ='키생성과정(Key Scheduling)'!E19 -> 2c | F27: ='키생성과정(Key Scheduling)'!F19 -> 39 | G27: ='키생성과정(Key Scheduling)'!G19 -> 76 | I27: 2 | J27: =LOWER(DEC2HEX(_xlfn.BITXOR(HEX2DEC(P20),HEX2DEC(D27)))) -> 7f | K27: =LOWER(DEC2HEX(_xlfn.BITXOR(HEX2DEC(Q20),HEX2DEC(E27)))) -> 35 | L27: =LOWER(DEC2HEX(_xlfn.BITXOR(HEX2DEC(R20),HEX2DEC(F27)))) -> ea | M27: =LOWER(DEC2HEX(_xlfn.BITXOR(HEX2DEC(S20),HEX2DEC(G27)))) -> 50 | U27: =$J$18 -> d4 | V27: =$J$19 -> bf | W27: =$J$20 -> 5d | X27: =$J$21 -> 30 | Z27: =$K$18 -> e0 | AA27: =$K$19 -> b4 | AB27: =$K$20 -> 52 | AC27: =$K$21 -> ae | AE27: =$L$18 -> b8 | AF27: =$L$19 -> 41 | AG27: =$L$20 -> 11 | AH27: =$L$21 -> f1 | AJ27: =$M$18 -> 1e | AK27: =$M$19 -> 27 | AL27: =$M$20 -> 98 | AM27: =$M$21 -> e5 | AO27: =$J$33 -> 49 | AP27: =$J$34 -> db | AQ27: =$J$35 -> 87 | AR27: =$J$36 -> 3b | AT27: =$K$33 -> 45 | AU27: =$K$34 -> 39 | AV27: =$K$35 -> 53 | AW27: =$K$36 -> 89 | AY27: =$L$33 -> 7f | AZ27: =$L$34 -> 02 | BA27: =$L$35 -> d2 | BB27: =$L$36 -> f1 | BD27: =$M$33 -> 77 | BE27: =$M$34 -> de | BF27: =$M$35 -> 96 | BG27: =$M$36 -> 1a
C28: 3 | D28: ='키생성과정(Key Scheduling)'!D20 -> 17 | E28: ='키생성과정(Key Scheduling)'!E20 -> b1 | F28: ='키생성과정(Key Scheduling)'!F20 -> 39 | G28: ='키생성과정(Key Scheduling)'!G20 -> 05 | I28: 3 | J28: =LOWER(DEC2HEX(_xlfn.BITXOR(HEX2DEC(P21),HEX2DEC(D28)))) -> f2 | K28: =LOWER(DEC2HEX(_xlfn.BITXOR(HEX2DEC(Q21),HEX2DEC(E28)))) -> 2b | L28: =LOWER(DEC2HEX(_xlfn.BITXOR(HEX2DEC(R21),HEX2DEC(F28)))) -> 43 | M28: =LOWER(DEC2HEX(_xlfn.BITXOR(HEX2DEC(S21),HEX2DEC(G28)))) -> 49 | U28: =U27 -> d4 | Z28: =Z27 -> e0 | AE28: =AE27 -> b8 | AJ28: =AJ27 -> 1e | AO28: =AO27 -> 49 | AT28: =AT27 -> 45 | AY28: =AY27 -> 7f | BD28: =BD27 -> 77
V29: =V27 -> bf | AA29: =AA27 -> b4 | AF29: =AF27 -> 41 | AK29: =AK27 -> 27 | AP29: =AP27 -> db | AU29: =AU27 -> 39 | AZ29: =AZ27 -> 02 | BE29: =BE27 -> de
C30: 2라운드 AES 계산 결과 (=3라운드 AES 계산 입력) | V30: =IF(HEX2DEC(V29)>127,DEC2HEX(_xlfn.BITXOR(_xlfn.BITLSHIFT(HEX2DEC(V29)-128,1),HEX2DEC("1B"))),DEC2HEX(_xlfn.BITLSHIFT(HEX2DEC(V29),1))) -> 65 | AA30: =IF(HEX2DEC(AA29)>127,DEC2HEX(_xlfn.BITXOR(_xlfn.BITLSHIFT(HEX2DEC(AA29)-128,1),HEX2DEC("1B"))),DEC2HEX(_xlfn.BITLSHIFT(HEX2DEC(AA29),1))) -> 73 | AF30: =IF(HEX2DEC(AF29)>127,DEC2HEX(_xlfn.BITXOR(_xlfn.BITLSHIFT(HEX2DEC(AF29)-128,1),HEX2DEC("1B"))),DEC2HEX(_xlfn.BITLSHIFT(HEX2DEC(AF29),1))) -> 82 | AK30: =IF(HEX2DEC(AK29)>127,DEC2HEX(_xlfn.BITXOR(_xlfn.BITLSHIFT(HEX2DEC(AK29)-128,1),HEX2DEC("1B"))),DEC2HEX(_xlfn.BITLSHIFT(HEX2DEC(AK29),1))) -> 4E | AP30: =IF(HEX2DEC(AP29)>127,DEC2HEX(_xlfn.BITXOR(_xlfn.BITLSHIFT(HEX2DEC(AP29)-128,1),HEX2DEC("1B"))),DEC2HEX(_xlfn.BITLSHIFT(HEX2DEC(AP29),1))) -> AD | AU30: =IF(HEX2DEC(AU29)>127,DEC2HEX(_xlfn.BITXOR(_xlfn.BITLSHIFT(HEX2DEC(AU29)-128,1),HEX2DEC("1B"))),DEC2HEX(_xlfn.BITLSHIFT(HEX2DEC(AU29),1))) -> 72 | AZ30: =IF(HEX2DEC(AZ29)>127,DEC2HEX(_xlfn.BITXOR(_xlfn.BITLSHIFT(HEX2DEC(AZ29)-128,1),HEX2DEC("1B"))),DEC2HEX(_xlfn.BITLSHIFT(HEX2DEC(AZ29),1))) -> 4 | BE30: =IF(HEX2DEC(BE29)>127,DEC2HEX(_xlfn.BITXOR(_xlfn.BITLSHIFT(HEX2DEC(BE29)-128,1),HEX2DEC("1B"))),DEC2HEX(_xlfn.BITLSHIFT(HEX2DEC(BE29),1))) -> A7
C31: After SubBytes | I31: After ShiftRows | O31: After MixColumns | W31: =W27 -> 5d | AB31: =AB27 -> 52 | AG31: =AG27 -> 11 | AL31: =AL27 -> 98 | AQ31: =AQ27 -> 87 | AV31: =AV27 -> 53 | BA31: =BA27 -> d2 | BF31: =BF27 -> 96
D32: 0 | E32: 1 | F32: 2 | G32: 3 | J32: 0 | K32: 1 | L32: 2 | M32: 3 | P32: 0 | Q32: 1 | R32: 2 | S32: 3 | W32: =IF(HEX2DEC(W31)>127,DEC2HEX(_xlfn.BITXOR(_xlfn.BITLSHIFT(HEX2DEC(W31)-128,1),HEX2DEC("1B"))),DEC2HEX(_xlfn.BITLSHIFT(HEX2DEC(W31),1))) -> BA | AB32: =IF(HEX2DEC(AB31)>127,DEC2HEX(_xlfn.BITXOR(_xlfn.BITLSHIFT(HEX2DEC(AB31)-128,1),HEX2DEC("1B"))),DEC2HEX(_xlfn.BITLSHIFT(HEX2DEC(AB31),1))) -> A4 | AG32: =IF(HEX2DEC(AG31)>127,DEC2HEX(_xlfn.BITXOR(_xlfn.BITLSHIFT(HEX2DEC(AG31)-128,1),HEX2DEC("1B"))),DEC2HEX(_xlfn.BITLSHIFT(HEX2DEC(AG31),1))) -> 22 | AL32: =IF(HEX2DEC(AL31)>127,DEC2HEX(_xlfn.BITXOR(_xlfn.BITLSHIFT(HEX2DEC(AL31)-128,1),HEX2DEC("1B"))),DEC2HEX(_xlfn.BITLSHIFT(HEX2DEC(AL31),1))) -> 2B | AQ32: =IF(HEX2DEC(AQ31)>127,DEC2HEX(_xlfn.BITXOR(_xlfn.BITLSHIFT(HEX2DEC(AQ31)-128,1),HEX2DEC("1B"))),DEC2HEX(_xlfn.BITLSHIFT(HEX2DEC(AQ31),1))) -> 15 | AV32: =IF(HEX2DEC(AV31)>127,DEC2HEX(_xlfn.BITXOR(_xlfn.BITLSHIFT(HEX2DEC(AV31)-128,1),HEX2DEC("1B"))),DEC2HEX(_xlfn.BITLSHIFT(HEX2DEC(AV31),1))) -> A6 | BA32: =IF(HEX2DEC(BA31)>127,DEC2HEX(_xlfn.BITXOR(_xlfn.BITLSHIFT(HEX2DEC(BA31)-128,1),HEX2DEC("1B"))),DEC2HEX(_xlfn.BITLSHIFT(HEX2DEC(BA31),1))) -> BF | BF32: =IF(HEX2DEC(BF31)>127,DEC2HEX(_xlfn.BITXOR(_xlfn.BITLSHIFT(HEX2DEC(BF31)-128,1),HEX2DEC("1B"))),DEC2HEX(_xlfn.BITLSHIFT(HEX2DEC(BF31),1))) -> 37
C33: 0 | D33: {=INDEX('S-box'!$D$5:$S$20,HEX2DEC(LEFT(J25,1))+1, HEX2DEC(RIGHT(J25,1))+1)} -> 49 | E33: {=INDEX('S-box'!$D$5:$S$20,HEX2DEC(LEFT(K25,1))+1, HEX2DEC(RIGHT(K25,1))+1)} -> 45 | F33: {=INDEX('S-box'!$D$5:$S$20,HEX2DEC(LEFT(L25,1))+1, HEX2DEC(RIGHT(L25,1))+1)} -> 7f | G33: {=INDEX('S-box'!$D$5:$S$20,HEX2DEC(LEFT(M25,1))+1, HEX2DEC(RIGHT(M25,1))+1)} -> 77 | I33: 0 | J33: =D33 -> 49 | K33: =E33 -> 45 | L33: =F33 -> 7f | M33: =G33 -> 77 | O33: 0 | P33: =AO26 -> 58 | Q33: =AT26 -> 1b | R33: =AY26 -> db | S33: =BD26 -> 1B | W33: =DEC2HEX(_xlfn.BITXOR(HEX2DEC(W$31),HEX2DEC(W$32))) -> E7 | AB33: =DEC2HEX(_xlfn.BITXOR(HEX2DEC(AB31),HEX2DEC(AB32))) -> F6 | AG33: =DEC2HEX(_xlfn.BITXOR(HEX2DEC(AG31),HEX2DEC(AG32))) -> 33 | AL33: =DEC2HEX(_xlfn.BITXOR(HEX2DEC(AL31),HEX2DEC(AL32))) -> B3 | AQ33: =DEC2HEX(_xlfn.BITXOR(HEX2DEC(AQ$31),HEX2DEC(AQ$32))) -> 92 | AV33: =DEC2HEX(_xlfn.BITXOR(HEX2DEC(AV31),HEX2DEC(AV32))) -> F5 | BA33: =DEC2HEX(_xlfn.BITXOR(HEX2DEC(BA31),HEX2DEC(BA32))) -> 6D | BF33: =DEC2HEX(_xlfn.BITXOR(HEX2DEC(BF31),HEX2DEC(BF32))) -> A1
C34: 1 | D34: {=INDEX('S-box'!$D$5:$S$20,HEX2DEC(LEFT(J26,1))+1, HEX2DEC(RIGHT(J26,1))+1)} -> de | E34: {=INDEX('S-box'!$D$5:$S$20,HEX2DEC(LEFT(K26,1))+1, HEX2DEC(RIGHT(K26,1))+1)} -> db | F34: {=INDEX('S-box'!$D$5:$S$20,HEX2DEC(LEFT(L26,1))+1, HEX2DEC(RIGHT(L26,1))+1)} -> 39 | G34: {=INDEX('S-box'!$D$5:$S$20,HEX2DEC(LEFT(M26,1))+1, HEX2DEC(RIGHT(M26,1))+1)} -> 02 | I34: 1 | J34: =E34 -> db | K34: =F34 -> 39 | L34: =G34 -> 02 | M34: =D34 -> de | O34: 1 | P34: =AP35 -> 4d | Q34: =AU35 -> 4b | R34: =AZ35 -> e7 | S34: =BE35 -> 6B | X34: =X27 -> 30 | AC34: =AC27 -> ae | AH34: =AH27 -> f1 | AM34: =AM27 -> e5 | AR34: =AR27 -> 3b | AW34: =AW27 -> 89 | BB34: =BB27 -> f1 | BG34: =BG27 -> 1a
C35: 2 | D35: {=INDEX('S-box'!$D$5:$S$20,HEX2DEC(LEFT(J27,1))+1, HEX2DEC(RIGHT(J27,1))+1)} -> d2 | E35: {=INDEX('S-box'!$D$5:$S$20,HEX2DEC(LEFT(K27,1))+1, HEX2DEC(RIGHT(K27,1))+1)} -> 96 | F35: {=INDEX('S-box'!$D$5:$S$20,HEX2DEC(LEFT(L27,1))+1, HEX2DEC(RIGHT(L27,1))+1)} -> 87 | G35: {=INDEX('S-box'!$D$5:$S$20,HEX2DEC(LEFT(M27,1))+1, HEX2DEC(RIGHT(M27,1))+1)} -> 53 | I35: 2 | J35: =F35 -> 87 | K35: =G35 -> 53 | L35: =D35 -> d2 | M35: =E35 -> 96 | O35: 2 | P35: =AQ44 -> ca | Q35: =AV44 -> 5a | R35: =BA44 -> ca | S35: =BF44 -> b0 | V35: =DEC2HEX(_xlfn.BITXOR(_xlfn.BITXOR(_xlfn.BITXOR(HEX2DEC(U$28),HEX2DEC(V$30)),HEX2DEC(W$33)),HEX2DEC(X$34))) -> 66 | AA35: =LOWER(DEC2HEX(_xlfn.BITXOR(_xlfn.BITXOR(_xlfn.BITXOR(HEX2DEC(Z28),HEX2DEC(AA30)),HEX2DEC(AB33)),HEX2DEC(AC34)))) -> cb | AF35: =LOWER(DEC2HEX(_xlfn.BITXOR(_xlfn.BITXOR(_xlfn.BITXOR(HEX2DEC(AE28),HEX2DEC(AF30)),HEX2DEC(AG33)),HEX2DEC(AH34)))) -> f8 | AK35: =IF(LEN(DEC2HEX(_xlfn.BITXOR(_xlfn.BITXOR(_xlfn.BITXOR(HEX2DEC(AJ28),HEX2DEC(AK30)),HEX2DEC(AL33)),HEX2DEC(AM34))))=1, "0"&DEC2HEX(_xlfn.BITXOR(_xlfn.BITXOR(_xlfn.BITXOR(HEX2DEC(AJ28),HEX2DEC(AK30)),HEX2DEC(AL33)),HEX2DEC(AM34))), DEC2HEX(_xlfn.BITXOR(_xlfn.BITXOR(_xlfn.BITXOR(HEX2DEC(AJ28),HEX2DEC(AK30)),HEX2DEC(AL33)),HEX2DEC(AM34)))) -> 06 | AP35: =LOWER(DEC2HEX(_xlfn.BITXOR(_xlfn.BITXOR(_xlfn.BITXOR(HEX2DEC(AO$28),HEX2DEC(AP$30)),HEX2DEC(AQ$33)),HEX2DEC(AR$34)))) -> 4d | AU35: =LOWER(DEC2HEX(_xlfn.BITXOR(_xlfn.BITXOR(_xlfn.BITXOR(HEX2DEC(AT28),HEX2DEC(AU30)),HEX2DEC(AV33)),HEX2DEC(AW34)))) -> 4b | AZ35: =LOWER(DEC2HEX(_xlfn.BITXOR(_xlfn.BITXOR(_xlfn.BITXOR(HEX2DEC(AY28),HEX2DEC(AZ30)),HEX2DEC(BA33)),HEX2DEC(BB34)))) -> e7 | BE35: =IF(LEN(DEC2HEX(_xlfn.BITXOR(_xlfn.BITXOR(_xlfn.BITXOR(HEX2DEC(BD28),HEX2DEC(BE30)),HEX2DEC(BF33)),HEX2DEC(BG34))))=1, "0"&DEC2HEX(_xlfn.BITXOR(_xlfn.BITXOR(_xlfn.BITXOR(HEX2DEC(BD28),HEX2DEC(BE30)),HEX2DEC(BF33)),HEX2DEC(BG34))), DEC2HEX(_xlfn.BITXOR(_xlfn.BITXOR(_xlfn.BITXOR(HEX2DEC(BD28),HEX2DEC(BE30)),HEX2DEC(BF33)),HEX2DEC(BG34)))) -> 6B
C36: 3 | D36: {=INDEX('S-box'!$D$5:$S$20,HEX2DEC(LEFT(J28,1))+1, HEX2DEC(RIGHT(J28,1))+1)} -> 89 | E36: {=INDEX('S-box'!$D$5:$S$20,HEX2DEC(LEFT(K28,1))+1, HEX2DEC(RIGHT(K28,1))+1)} -> f1 | F36: {=INDEX('S-box'!$D$5:$S$20,HEX2DEC(LEFT(L28,1))+1, HEX2DEC(RIGHT(L28,1))+1)} -> 1a | G36: {=INDEX('S-box'!$D$5:$S$20,HEX2DEC(LEFT(M28,1))+1, HEX2DEC(RIGHT(M28,1))+1)} -> 3b | I36: 3 | J36: =G36 -> 3b | K36: =D36 -> 89 | L36: =E36 -> f1 | M36: =F36 -> 1a | O36: 3 | P36: =AR53 -> f1 | Q36: =AW53 -> ac | R36: =BB53 -> a8 | S36: =BG53 -> e5 | U36: =$J$18 -> d4 | V36: =$J$19 -> bf | W36: =$J$20 -> 5d | X36: =$J$21 -> 30 | Z36: =$K$18 -> e0 | AA36: =$K$19 -> b4 | AB36: =$K$20 -> 52 | AC36: =$K$21 -> ae | AE36: =$L$18 -> b8 | AF36: =$L$19 -> 41 | AG36: =$L$20 -> 11 | AH36: =$L$21 -> f1 | AJ36: =$M$18 -> 1e | AK36: =$M$19 -> 27 | AL36: =$M$20 -> 98 | AM36: =$M$21 -> e5 | AO36: =$J$33 -> 49 | AP36: =$J$34 -> db | AQ36: =$J$35 -> 87 | AR36: =$J$36 -> 3b | AT36: =$K$33 -> 45 | AU36: =$K$34 -> 39 | AV36: =$K$35 -> 53 | AW36: =$K$36 -> 89 | AY36: =$L$33 -> 7f | AZ36: =$L$34 -> 02 | BA36: =$L$35 -> d2 | BB36: =$L$36 -> f1 | BD36: =$M$33 -> 77 | BE36: =$M$34 -> de | BF36: =$M$35 -> 96 | BG36: =$M$36 -> 1a
U37: =U36 -> d4 | Z37: =Z36 -> e0 | AE37: =AE36 -> b8 | AJ37: =AJ36 -> 1e | AO37: =AO36 -> 49 | AT37: =AT36 -> 45 | AY37: =AY36 -> 7f | BD37: =BD36 -> 77
C38: Round key | I38: After AddRoundKey | V38: =V36 -> bf | AA38: =AA36 -> b4 | AF38: =AF36 -> 41 | AK38: =AK36 -> 27 | AP38: =AP36 -> db | AU38: =AU36 -> 39 | AZ38: =AZ36 -> 02 | BE38: =BE36 -> de
D39: 0 | E39: 1 | F39: 2 | G39: 3 | J39: 0 | K39: 1 | L39: 2 | M39: 3 | W39: =W36 -> 5d | AB39: =AB36 -> 52 | AG39: =AG36 -> 11 | AL39: =AL36 -> 98 | AQ39: =AQ36 -> 87 | AV39: =AV36 -> 53 | BA39: =BA36 -> d2 | BF39: =BF36 -> 96
C40: 0 | D40: ='키생성과정(Key Scheduling)'!O25 -> f2 | E40: ='키생성과정(Key Scheduling)'!P25 -> 7a | F40: ='키생성과정(Key Scheduling)'!Q25 -> 59 | G40: ='키생성과정(Key Scheduling)'!R25 -> 73 | I40: 0 | J40: =LOWER(DEC2HEX(_xlfn.BITXOR(HEX2DEC(P33),HEX2DEC(D40)))) -> aa | K40: =LOWER(DEC2HEX(_xlfn.BITXOR(HEX2DEC(Q33),HEX2DEC(E40)))) -> 61 | L40: =LOWER(DEC2HEX(_xlfn.BITXOR(HEX2DEC(R33),HEX2DEC(F40)))) -> 82 | M40: =IF(LEN(DEC2HEX(_xlfn.BITXOR(HEX2DEC(S33),HEX2DEC(G40))))=1, "0"&DEC2HEX(_xlfn.BITXOR(HEX2DEC(S33),HEX2DEC(G40))), DEC2HEX(_xlfn.BITXOR(HEX2DEC(S33),HEX2DEC(G40)))) -> 68 | W40: =IF(HEX2DEC(W39)>127,DEC2HEX(_xlfn.BITXOR(_xlfn.BITLSHIFT(HEX2DEC(W39)-128,1),HEX2DEC("1B"))),DEC2HEX(_xlfn.BITLSHIFT(HEX2DEC(W39),1))) -> BA | AB40: =IF(HEX2DEC(AB39)>127,DEC2HEX(_xlfn.BITXOR(_xlfn.BITLSHIFT(HEX2DEC(AB39)-128,1),HEX2DEC("1B"))),DEC2HEX(_xlfn.BITLSHIFT(HEX2DEC(AB39),1))) -> A4 | AG40: =IF(HEX2DEC(AG39)>127,DEC2HEX(_xlfn.BITXOR(_xlfn.BITLSHIFT(HEX2DEC(AG39)-128,1),HEX2DEC("1B"))),DEC2HEX(_xlfn.BITLSHIFT(HEX2DEC(AG39),1))) -> 22 | AL40: =IF(HEX2DEC(AL39)>127,DEC2HEX(_xlfn.BITXOR(_xlfn.BITLSHIFT(HEX2DEC(AL39)-128,1),HEX2DEC("1B"))),DEC2HEX(_xlfn.BITLSHIFT(HEX2DEC(AL39),1))) -> 2B | AQ40: =IF(HEX2DEC(AQ39)>127,DEC2HEX(_xlfn.BITXOR(_xlfn.BITLSHIFT(HEX2DEC(AQ39)-128,1),HEX2DEC("1B"))),DEC2HEX(_xlfn.BITLSHIFT(HEX2DEC(AQ39),1))) -> 15 | AV40: =IF(HEX2DEC(AV39)>127,DEC2HEX(_xlfn.BITXOR(_xlfn.BITLSHIFT(HEX2DEC(AV39)-128,1),HEX2DEC("1B"))),DEC2HEX(_xlfn.BITLSHIFT(HEX2DEC(AV39),1))) -> A6 | BA40: =IF(HEX2DEC(BA39)>127,DEC2HEX(_xlfn.BITXOR(_xlfn.BITLSHIFT(HEX2DEC(BA39)-128,1),HEX2DEC("1B"))),DEC2HEX(_xlfn.BITLSHIFT(HEX2DEC(BA39),1))) -> BF | BF40: =IF(HEX2DEC(BF39)>127,DEC2HEX(_xlfn.BITXOR(_xlfn.BITLSHIFT(HEX2DEC(BF39)-128,1),HEX2DEC("1B"))),DEC2HEX(_xlfn.BITLSHIFT(HEX2DEC(BF39),1))) -> 37
C41: 1 | D41: ='키생성과정(Key Scheduling)'!O26 -> c2 | E41: ='키생성과정(Key Scheduling)'!P26 -> 96 | F41: ='키생성과정(Key Scheduling)'!Q26 -> 35 | G41: ='키생성과정(Key Scheduling)'!R26 -> 59 | I41: 1 | J41: =LOWER(DEC2HEX(_xlfn.BITXOR(HEX2DEC(P34),HEX2DEC(D41)))) -> 8f | K41: =LOWER(DEC2HEX(_xlfn.BITXOR(HEX2DEC(Q34),HEX2DEC(E41)))) -> dd | L41: =LOWER(DEC2HEX(_xlfn.BITXOR(HEX2DEC(R34),HEX2DEC(F41)))) -> d2 | M41: =LOWER(DEC2HEX(_xlfn.BITXOR(HEX2DEC(S34),HEX2DEC(G41)))) -> 32 | X41: =X36 -> 30 | AC41: =AC36 -> ae | AH41: =AH36 -> f1 | AM41: =AM36 -> e5 | AR41: =AR36 -> 3b | AW41: =AW36 -> 89 | BB41: =BB36 -> f1 | BG41: =BG36 -> 1a
C42: 2 | D42: ='키생성과정(Key Scheduling)'!O27 -> 95 | E42: ='키생성과정(Key Scheduling)'!P27 -> b9 | F42: ='키생성과정(Key Scheduling)'!Q27 -> 80 | G42: ='키생성과정(Key Scheduling)'!R27 -> f6 | I42: 2 | J42: =LOWER(DEC2HEX(_xlfn.BITXOR(HEX2DEC(P35),HEX2DEC(D42)))) -> 5f | K42: =LOWER(DEC2HEX(_xlfn.BITXOR(HEX2DEC(Q35),HEX2DEC(E42)))) -> e3 | L42: =LOWER(DEC2HEX(_xlfn.BITXOR(HEX2DEC(R35),HEX2DEC(F42)))) -> 4a | M42: =LOWER(DEC2HEX(_xlfn.BITXOR(HEX2DEC(S35),HEX2DEC(G42)))) -> 46 | X42: =IF(HEX2DEC(X41)>127,DEC2HEX(_xlfn.BITXOR(_xlfn.BITLSHIFT(HEX2DEC(X41)-128,1),HEX2DEC("1B"))),DEC2HEX(_xlfn.BITLSHIFT(HEX2DEC(X41),1))) -> 60 | AC42: =IF(HEX2DEC(AC41)>127,DEC2HEX(_xlfn.BITXOR(_xlfn.BITLSHIFT(HEX2DEC(AC41)-128,1),HEX2DEC("1B"))),DEC2HEX(_xlfn.BITLSHIFT(HEX2DEC(AC41),1))) -> 47 | AH42: =IF(HEX2DEC(AH41)>127,DEC2HEX(_xlfn.BITXOR(_xlfn.BITLSHIFT(HEX2DEC(AH41)-128,1),HEX2DEC("1B"))),DEC2HEX(_xlfn.BITLSHIFT(HEX2DEC(AH41),1))) -> F9 | AM42: =IF(HEX2DEC(AM41)>127,DEC2HEX(_xlfn.BITXOR(_xlfn.BITLSHIFT(HEX2DEC(AM41)-128,1),HEX2DEC("1B"))),DEC2HEX(_xlfn.BITLSHIFT(HEX2DEC(AM41),1))) -> D1 | AR42: =IF(HEX2DEC(AR41)>127,DEC2HEX(_xlfn.BITXOR(_xlfn.BITLSHIFT(HEX2DEC(AR41)-128,1),HEX2DEC("1B"))),DEC2HEX(_xlfn.BITLSHIFT(HEX2DEC(AR41),1))) -> 76 | AW42: =IF(HEX2DEC(AW41)>127,DEC2HEX(_xlfn.BITXOR(_xlfn.BITLSHIFT(HEX2DEC(AW41)-128,1),HEX2DEC("1B"))),DEC2HEX(_xlfn.BITLSHIFT(HEX2DEC(AW41),1))) -> 9 | BB42: =IF(HEX2DEC(BB41)>127,DEC2HEX(_xlfn.BITXOR(_xlfn.BITLSHIFT(HEX2DEC(BB41)-128,1),HEX2DEC("1B"))),DEC2HEX(_xlfn.BITLSHIFT(HEX2DEC(BB41),1))) -> F9 | BG42: =IF(HEX2DEC(BG41)>127,DEC2HEX(_xlfn.BITXOR(_xlfn.BITLSHIFT(HEX2DEC(BG41)-128,1),HEX2DEC("1B"))),DEC2HEX(_xlfn.BITLSHIFT(HEX2DEC(BG41),1))) -> 34
C43: 3 | D43: ='키생성과정(Key Scheduling)'!O28 -> f2 | E43: ='키생성과정(Key Scheduling)'!P28 -> 43 | F43: ='키생성과정(Key Scheduling)'!Q28 -> 7a | G43: ='키생성과정(Key Scheduling)'!R28 -> 7f | I43: 3 | J43: =IF(LEN(DEC2HEX(_xlfn.BITXOR(HEX2DEC(P36),HEX2DEC(D43))))=1, "0"&DEC2HEX(_xlfn.BITXOR(HEX2DEC(P36),HEX2DEC(D43))), DEC2HEX(_xlfn.BITXOR(HEX2DEC(P36),HEX2DEC(D43)))) -> 03 | K43: =LOWER(DEC2HEX(_xlfn.BITXOR(HEX2DEC(Q36),HEX2DEC(E43)))) -> ef | L43: =LOWER(DEC2HEX(_xlfn.BITXOR(HEX2DEC(R36),HEX2DEC(F43)))) -> d2 | M43: =LOWER(DEC2HEX(_xlfn.BITXOR(HEX2DEC(S36),HEX2DEC(G43)))) -> 9a | X43: =DEC2HEX(_xlfn.BITXOR(HEX2DEC(X41),HEX2DEC(X42))) -> 50 | AC43: =DEC2HEX(_xlfn.BITXOR(HEX2DEC(AC41),HEX2DEC(AC42))) -> E9 | AH43: =DEC2HEX(_xlfn.BITXOR(HEX2DEC(AH41),HEX2DEC(AH42))) -> 8 | AM43: =DEC2HEX(_xlfn.BITXOR(HEX2DEC(AM41),HEX2DEC(AM42))) -> 34 | AR43: =DEC2HEX(_xlfn.BITXOR(HEX2DEC(AR41),HEX2DEC(AR42))) -> 4D | AW43: =DEC2HEX(_xlfn.BITXOR(HEX2DEC(AW41),HEX2DEC(AW42))) -> 80 | BB43: =DEC2HEX(_xlfn.BITXOR(HEX2DEC(BB41),HEX2DEC(BB42))) -> 8 | BG43: =DEC2HEX(_xlfn.BITXOR(HEX2DEC(BG41),HEX2DEC(BG42))) -> 2E
...

Sheet S-box
B2: *3 AES 암호화의 S-box table
B3: HEX | D3: y | U3: ※ 해당 S-box를 참고하되, 앞 시트 연산(키생성, 암호화 과정)을 위해서 표를 수정해도 무관함
D4: 0 | E4: 1 | F4: 2 | G4: 3 | H4: 4 | I4: 5 | J4: 6 | K4: 7 | L4: 8 | M4: 9 | N4: A | O4: B | P4: C | Q4: D | R4: E | S4: F
B5: x | C5: 0 | D5: 63 | E5: 7c | F5: 77 | G5: 7b | H5: f2 | I5: 6b | J5: 6f | K5: c5 | L5: 30 | M5: 01 | N5: 67 | O5: 2b | P5: fe | Q5: d7 | R5: ab | S5: 76
C6: 1 | D6: ca | E6: 82 | F6: c9 | G6: 7d | H6: fa | I6: 59 | J6: 47 | K6: f0 | L6: ad | M6: d4 | N6: a2 | O6: af | P6: 9c | Q6: a4 | R6: 72 | S6: c0
C7: 2 | D7: b7 | E7: fd | F7: 93 | G7: 26 | H7: 36 | I7: 3f | J7: f7 | K7: cc | L7: 34 | M7: a5 | N7: e5 | O7: f1 | P7: 71 | Q7: d8 | R7: 31 | S7: 15
C8: 3 | D8: 04 | E8: c7 | F8: 23 | G8: c3 | H8: 18 | I8: 96 | J8: 05 | K8: 9a | L8: 07 | M8: 12 | N8: 80 | O8: e2 | P8: eb | Q8: 27 | R8: b2 | S8: 75
C9: 4 | D9: 09 | E9: 83 | F9: 2c | G9: 1a | H9: 1b | I9: 6e | J9: 5a | K9: a0 | L9: 52 | M9: 3b | N9: d6 | O9: b3 | P9: 29 | Q9: e3 | R9: 2f | S9: 84
C10: 5 | D10: 53 | E10: d1 | F10: 00 | G10: ed | H10: 20 | I10: fc | J10: b1 | K10: 5b | L10: 6a | M10: cb | N10: be | O10: 39 | P10: 4a | Q10: 4c | R10: 58 | S10: cf
C11: 6 | D11: d0 | E11: ef | F11: aa | G11: fb | H11: 43 | I11: 4d | J11: 33 | K11: 85 | L11: 45 | M11: f9 | N11: 02 | O11: 7f | P11: 50 | Q11: 3c | R11: 9f | S11: a8
C12: 7 | D12: 51 | E12: a3 | F12: 40 | G12: 8f | H12: 92 | I12: 9d | J12: 38 | K12: f5 | L12: bc | M12: b6 | N12: da | O12: 21 | P12: 10 | Q12: ff | R12: f3 | S12: d2
C13: 8 | D13: cd | E13: 0c | F13: 13 | G13: ec | H13: 5f | I13: 97 | J13: 44 | K13: 17 | L13: c4 | M13: a7 | N13: 7e | O13: 3d | P13: 64 | Q13: 5d | R13: 19 | S13: 73
C14: 9 | D14: 60 | E14: 81 | F14: 4f | G14: dc | H14: 22 | I14: 2a | J14: 90 | K14: 88 | L14: 46 | M14: ee | N14: b8 | O14: 14 | P14: de | Q14: 5e | R14: 0b | S14: db
C15: A | D15: e0 | E15: 32 | F15: 3a | G15: 0a | H15: 49 | I15: 06 | J15: 24 | K15: 5c | L15: c2 | M15: d3 | N15: ac | O15: 62 | P15: 91 | Q15: 95 | R15: e4 | S15: 79
C16: B | D16: e7 | E16: c8 | F16: 37 | G16: 6d | H16: 8d | I16: d5 | J16: 4e | K16: a9 | L16: 6c | M16: 56 | N16: f4 | O16: ea | P16: 65 | Q16: 7a | R16: ae | S16: 08
C17: C | D17: ba | E17: 78 | F17: 25 | G17: 2e | H17: 1c | I17: a6 | J17: b4 | K17: c6 | L17: e8 | M17: dd | N17: 74 | O17: 1f | P17: 4b | Q17: bd | R17: 8b | S17: 8a
C18: D | D18: 70 | E18: 3e | F18: b5 | G18: 66 | H18: 48 | I18: 03 | J18: f6 | K18: 0e | L18: 61 | M18: 35 | N18: 57 | O18: b9 | P18: 86 | Q18: c1 | R18: 1d | S18: 9e
C19: E | D19: e1 | E19: f8 | F19: 98 | G19: 11 | H19: 69 | I19: d9 | J19: 8e | K19: 94 | L19: 9b | M19: 1e | N19: 87 | O19: e9 | P19: ce | Q19: 55 | R19: 28 | S19: df
C20: F | D20: 8c | E20: a1 | F20: 89 | G20: 0d | H20: bf | I20: e6 | J20: 42 | K20: 68 | L20: 41 | M20: 99 | N20: 2d | O20: 0f | P20: b0 | Q20: 54 | R20: bb | S20: 16
